[tests/libs/error_trace_test.ca:8 inside main()] 
 [tests/libs/error_trace_test.ca:6 inside func()] 
  [inside error()] 
   Error: an error occurred!
